<?xml version="1.0" encoding="UTF-8"?>
<robot name="lfl" xmlns:xacro="http://ros.org/wiki/xacro">


<xacro:include filename="$(find minilift_description)/urdf/materials.xacro" />
<xacro:include filename="$(find minilift_description)/urdf/macros.xacro" />

<xacro:macro name="lfl_base" params="prefix">

  <!-- BASE FOOTPRINT --> 

  <!-- <link name="${prefix}_lfl_base_footprint"/>

  <joint name="${prefix}_lfl_base_footprint_joint" type="fixed">
    <parent link="${prefix}_lfl_base_footprint"/>
    <child link="${prefix}_lfl_base"/>
  </joint> -->

  <!-- BASE LINK -->

  <link name="${prefix}_lfl_base">
    <visual>
      <origin xyz="0 0 0.0605" rpy="0 0 0"/>
      <geometry>
        <mesh filename="package://minilift_description/meshes/visual/LFL_xyz.stl"/>
      </geometry>
      <material name="dark_grey"/>
    </visual>
    <collision>
      <origin xyz="0 0 0.0605" rpy="0 0 0"/>
      <geometry>
        <mesh filename="package://minilift_description/meshes/collision/steel_base.stl"/>
      </geometry>
    </collision>
  <inertial>
    <origin xyz=".15 0 0.2" rpy="0 0 0"/>   <!-- Given -->
    <mass value="0"/>
    <inertia ixx="0.2" ixy="0.0" ixz="0.0" iyy="0.01" iyz="0.0" izz="0.01"/>
  </inertial>
  </link>

  <gazebo reference="${prefix}_lfl_base">
    <material>Gazebo/DarkGrey</material>
  </gazebo>


  <!-- LIFTPLATE -->

  <link name="${prefix}_lfl_liftplate">
    <visual>
      <origin xyz="0 0 0" rpy="0 0 3.14159"/>
      <geometry>
        <mesh filename="package://minilift_description/meshes/visual/LFL_liftplate.stl"/>
      </geometry>
      <material name="dark_grey"/>
    </visual>
    <collision>
      <origin xyz="0 0 0" rpy="0 0 3.14159"/>
      <geometry>
        <mesh filename="package://minilift_description/meshes/collision/LFL_liftplate.stl"/>
      </geometry>
    </collision>
  <inertial>
    <mass value="1"/>
    <inertia ixx="0.01" ixy="0.0" ixz="0.0" iyy="0.01" iyz="0.0" izz="0.01"/>
  </inertial>
  </link>

  <gazebo reference="${prefix}_lfl_liftplate">
    <material>Gazebo/DarkGrey</material>
  </gazebo>

  <joint name="${prefix}_lfl_lift" type="prismatic">
      <origin rpy="0 0 3.14159" xyz="0.22 0.0 1"/>
      <parent link="${prefix}_lfl_base"/>
      <child link="${prefix}_lfl_liftplate"/>
      <axis xyz="0 0 1"/>
      <limit effort="100.0" lower="0.15" upper="0.56" velocity="0.05"/>
      <dynamics damping="0.5" friction="0.06"/>
  </joint>

  <!-- transmissions for Gazebo -->

  <transmission name="${prefix}_lfl_lift_trans">
    <type>transmission_interface/SimpleTransmission</type>
    <joint name="${prefix}_lfl_lift">
        <hardwareInterface>hardware_interface/PositionJointInterface</hardwareInterface>
    </joint>
    <actuator name="${prefix}_lfl_lift_motor">
        <mechanicalReduction>1</mechanicalReduction>
        <hardwareInterface>hardware_interface/PositionJointInterface</hardwareInterface>
    </actuator>
  </transmission>


  <!-- LEFT TRACTION WHEEL -->

  <link name="${prefix}_left_wheel_link">
    <visual>
      <origin xyz="0 0.0 0" rpy="-1.571 0 0"/>
      <geometry>
        <cylinder length="0.05" radius="0.0605"/>
      </geometry>
      <material name="black"/>
    </visual>
    <collision>
      <origin xyz="0 0.0 0" rpy="-1.571 0 0"/>
      <geometry>
        <cylinder length="0.05" radius="0.0605"/>
      </geometry>
    </collision>
  <inertial>
    <mass value="0.1"/>
    <xacro:cylinder_inertia m="0.1" r="0.0605" h="0.05"/>
  </inertial>
  </link>

  <gazebo reference="${prefix}_left_wheel_link">
    <material>Gazebo/Black</material>
  </gazebo>

  <joint name="${prefix}_lfl_to_left_wheel" type="continuous">
    <origin rpy="0.0 0 0" xyz="0.0 0.2625 0.0620"/>
    <parent link="${prefix}_lfl_base"/>
    <child link="${prefix}_left_wheel_link"/>
    <axis xyz="0 1 0"/>
  </joint>

  <!-- RIGHT TRACTION WHEEL -->

  <link name="${prefix}_right_wheel_link">
    <visual>
      <origin xyz="0 0.0 0" rpy="-1.571 0 0"/>
      <geometry>
        <cylinder length="0.05" radius="0.0605"/>
      </geometry>
      <material name="black"/>
    </visual>
    <collision>
      <origin xyz="0 0.0 0" rpy="-1.571 0 0"/>
      <geometry>
        <cylinder length="0.05" radius="0.0605"/>
      </geometry>
    </collision>
  <inertial>
    <mass value="0.1"/>
    <xacro:cylinder_inertia m="0.1" r="0.0605" h="0.05"/>
  </inertial>
  </link>

  <gazebo reference="${prefix}_right_wheel_link">
    <material>Gazebo/Black</material>
  </gazebo>


  <joint name="${prefix}_lfl_to_right_wheel" type="continuous">
      <origin rpy="0 0 0" xyz="0.0 -0.2625 0.0620"/>
      <parent link="${prefix}_lfl_base"/>
      <child link="${prefix}_right_wheel_link"/>
      <axis xyz="0 1 0"/>
  </joint>

 <!-- LEFT CASTOR WHEEL -->

  <link name="${prefix}_left_castor_wheel_link">
    <visual>
      <origin xyz="0 0.0 0" rpy="1.571 0 0"/>
      <geometry>
        <cylinder length="0.038" radius="0.038"/>
      </geometry>
      <material name="black"/>
    </visual>
    <collision>
      <origin xyz="0 0.0 0" rpy="1.571 0 0"/>
      <geometry>
        <cylinder length="0.038" radius="0.038"/>
      </geometry>
    </collision>
    <inertial>
      <mass value="0.1"/>
      <xacro:cylinder_inertia m="0.1" r="0.038" h="0.038"/>
    </inertial>
  </link>

  <gazebo reference="${prefix}_left_castor_wheel_link">
    <mu1 value="0.1"/>
    <mu2 value="0.1"/>
    <kp  value="10000000.0" />
    <kd  value="1.0" />
    <fdir1 value="1 0 0"/>
    <material>Gazebo/Black</material>
  </gazebo>

  <joint name="${prefix}_lfl_to_left_castor_wheel" type="continuous">
    <origin rpy="0.0 0 0" xyz="0.65 0.2565 0.0310"/>
    <parent link="${prefix}_lfl_base"/>
    <child link="${prefix}_left_castor_wheel_link"/>
    <axis xyz="0 1 0"/>
  </joint>


  <!-- RIGHT CASTOR WHEEL -->

  <link name="${prefix}_right_castor_wheel_link">
    <visual>
      <origin xyz="0 0.0 0" rpy="1.571 0 0"/>
      <geometry>
        <cylinder length="0.038" radius="0.038"/>
      </geometry>
      <material name="black"/>
    </visual>
    <collision>
      <origin xyz="0 0.0 0" rpy="1.571 0 0"/>
      <geometry>
        <cylinder length="0.038" radius="0.038"/>
      </geometry>
    </collision>
    <inertial>
      <mass value="0.1"/>
      <xacro:cylinder_inertia m="0.1" r="0.038" h="0.038"/>
    </inertial>
  </link>

  <gazebo reference="${prefix}_right_castor_wheel_link">
    <mu1 value="0.1"/>
    <mu2 value="0.1"/>
    <kp  value="10000000.0" />
    <kd  value="1.0" />
    <fdir1 value="1 0 0"/>
    <material>Gazebo/Black</material>
  </gazebo>

  <joint name="${prefix}_lfl_to_right_castor_wheel" type="continuous">
    <origin rpy="0.0 0 0" xyz="0.65 -0.2565 0.0310"/>
    <parent link="${prefix}_lfl_base"/>
    <child link="${prefix}_right_castor_wheel_link"/>
    <axis xyz="0 1 0"/>
  </joint>



<!--......................DIFFERENTIAL DRIVE PLUGIN .....................................-->

  <gazebo>
    <plugin name="differential_drive_controller" filename="libgazebo_ros_diff_drive.so">
      <robotNamespace>/</robotNamespace>
      <alwaysOn>true</alwaysOn>
      <updateRate>50</updateRate>
      <legacyMode>false</legacyMode>
      <leftJoint>${prefix}_lfl_to_left_wheel</leftJoint>
      <rightJoint>${prefix}_lfl_to_right_wheel</rightJoint>
      <wheelSeparation>0.5250</wheelSeparation>
      <wheelDiameter>0.1210</wheelDiameter>
      <commandTopic>cmd_vel</commandTopic>
      <odometryTopic>odom</odometryTopic>
      <odometryFrame>odom</odometryFrame>
      <robotBaseFrame>${prefix}_lfl_base</robotBaseFrame>
      <publishOdomTF>true</publishOdomTF>
      <publishWheelTF>false</publishWheelTF>
      <publishWheelJointState>false</publishWheelJointState>
      <rosDebugLevel>na</rosDebugLevel>
      <wheelAcceleration>0</wheelAcceleration>
      <wheelTorque>20</wheelTorque>
      <odometrySource>world</odometrySource>
      <publishTf>1</publishTf>
    </plugin>
  </gazebo>



<!-- ................................................................................ -->

</xacro:macro>
</robot>
